[2025-03-27T02:50:16.110+0000] {taskinstance.py:1103} INFO - Dependencies all met for dep_context=non-requeueable deps ti=<TaskInstance: load_geolocation_postgres_to_bq.postgres_to_gcs_batch_12 manual__2025-03-27T02:35:01.732554+00:00 [queued]>
[2025-03-27T02:50:16.125+0000] {taskinstance.py:1103} INFO - Dependencies all met for dep_context=requeueable deps ti=<TaskInstance: load_geolocation_postgres_to_bq.postgres_to_gcs_batch_12 manual__2025-03-27T02:35:01.732554+00:00 [queued]>
[2025-03-27T02:50:16.127+0000] {taskinstance.py:1308} INFO - Starting attempt 3 of 3
[2025-03-27T02:50:16.195+0000] {taskinstance.py:1327} INFO - Executing <Task(PostgresToGCSOperator): postgres_to_gcs_batch_12> on 2025-03-27 02:35:01.732554+00:00
[2025-03-27T02:50:16.273+0000] {standard_task_runner.py:57} INFO - Started process 6743 to run task
[2025-03-27T02:50:16.619+0000] {standard_task_runner.py:84} INFO - Running: ['airflow', 'tasks', 'run', 'load_geolocation_postgres_to_bq', 'postgres_to_gcs_batch_12', 'manual__2025-03-27T02:35:01.732554+00:00', '--job-id', '204', '--raw', '--subdir', 'DAGS_FOLDER/geolocation_postgres_to_bq.py', '--cfg-path', '/tmp/tmpg0gqy37d']
[2025-03-27T02:50:16.636+0000] {standard_task_runner.py:85} INFO - Job 204: Subtask postgres_to_gcs_batch_12
[2025-03-27T02:50:17.212+0000] {logging_mixin.py:149} WARNING - /home/airflow/.local/lib/python3.7/site-packages/airflow/settings.py:195 DeprecationWarning: The sql_alchemy_conn option in [core] has been moved to the sql_alchemy_conn option in [database] - the old setting has been used, but please update your config.
[2025-03-27T02:50:17.498+0000] {task_command.py:410} INFO - Running <TaskInstance: load_geolocation_postgres_to_bq.postgres_to_gcs_batch_12 manual__2025-03-27T02:35:01.732554+00:00 [running]> on host d0664e8a7014
[2025-03-27T02:50:17.760+0000] {taskinstance.py:1547} INFO - Exporting env vars: AIRFLOW_CTX_DAG_OWNER='Blessing Angus' AIRFLOW_CTX_DAG_ID='load_geolocation_postgres_to_bq' AIRFLOW_CTX_TASK_ID='postgres_to_gcs_batch_12' AIRFLOW_CTX_EXECUTION_DATE='2025-03-27T02:35:01.732554+00:00' AIRFLOW_CTX_TRY_NUMBER='3' AIRFLOW_CTX_DAG_RUN_ID='manual__2025-03-27T02:35:01.732554+00:00'
[2025-03-27T02:50:17.777+0000] {sql_to_gcs.py:155} INFO - Executing query
[2025-03-27T02:50:17.872+0000] {base.py:73} INFO - Using connection ID 'postgres_default' for task execution.
[2025-03-27T02:50:18.548+0000] {sql_to_gcs.py:174} INFO - Writing local data files
[2025-03-27T02:50:19.657+0000] {sql_to_gcs.py:180} INFO - Uploading chunk file #0 to GCS.
[2025-03-27T02:50:19.696+0000] {base.py:73} INFO - Using connection ID 'google_cloud_default' for task execution.
[2025-03-27T02:50:41.627+0000] {taskinstance.py:1824} ERROR - Task failed with exception
Traceback (most recent call last):
  File "/home/airflow/.local/lib/python3.7/site-packages/urllib3/connectionpool.py", line 721, in urlopen
    chunked=chunked,
  File "/home/airflow/.local/lib/python3.7/site-packages/urllib3/connectionpool.py", line 466, in _make_request
    six.raise_from(e, None)
  File "<string>", line 3, in raise_from
  File "/home/airflow/.local/lib/python3.7/site-packages/urllib3/connectionpool.py", line 461, in _make_request
    httplib_response = conn.getresponse()
  File "/usr/local/lib/python3.7/http/client.py", line 1373, in getresponse
    response.begin()
  File "/usr/local/lib/python3.7/http/client.py", line 319, in begin
    version, status, reason = self._read_status()
  File "/usr/local/lib/python3.7/http/client.py", line 288, in _read_status
    raise RemoteDisconnected("Remote end closed connection without"
http.client.RemoteDisconnected: Remote end closed connection without response

During handling of the above exception, another exception occurred:

Traceback (most recent call last):
  File "/home/airflow/.local/lib/python3.7/site-packages/requests/adapters.py", line 497, in send
    chunked=chunked,
  File "/home/airflow/.local/lib/python3.7/site-packages/urllib3/connectionpool.py", line 799, in urlopen
    method, url, error=e, _pool=self, _stacktrace=sys.exc_info()[2]
  File "/home/airflow/.local/lib/python3.7/site-packages/urllib3/util/retry.py", line 550, in increment
    raise six.reraise(type(error), error, _stacktrace)
  File "/home/airflow/.local/lib/python3.7/site-packages/urllib3/packages/six.py", line 769, in reraise
    raise value.with_traceback(tb)
  File "/home/airflow/.local/lib/python3.7/site-packages/urllib3/connectionpool.py", line 721, in urlopen
    chunked=chunked,
  File "/home/airflow/.local/lib/python3.7/site-packages/urllib3/connectionpool.py", line 466, in _make_request
    six.raise_from(e, None)
  File "<string>", line 3, in raise_from
  File "/home/airflow/.local/lib/python3.7/site-packages/urllib3/connectionpool.py", line 461, in _make_request
    httplib_response = conn.getresponse()
  File "/usr/local/lib/python3.7/http/client.py", line 1373, in getresponse
    response.begin()
  File "/usr/local/lib/python3.7/http/client.py", line 319, in begin
    version, status, reason = self._read_status()
  File "/usr/local/lib/python3.7/http/client.py", line 288, in _read_status
    raise RemoteDisconnected("Remote end closed connection without"
urllib3.exceptions.ProtocolError: ('Connection aborted.', RemoteDisconnected('Remote end closed connection without response'))

During handling of the above exception, another exception occurred:

Traceback (most recent call last):
  File "/home/airflow/.local/lib/python3.7/site-packages/airflow/providers/google/cloud/transfers/sql_to_gcs.py", line 181, in execute
    self._upload_to_gcs(file_to_upload)
  File "/home/airflow/.local/lib/python3.7/site-packages/airflow/providers/google/cloud/transfers/sql_to_gcs.py", line 475, in _upload_to_gcs
    metadata=metadata,
  File "/home/airflow/.local/lib/python3.7/site-packages/airflow/providers/google/cloud/hooks/gcs.py", line 533, in upload
    partial(blob.upload_from_filename, filename=filename, content_type=mime_type, timeout=timeout)
  File "/home/airflow/.local/lib/python3.7/site-packages/airflow/providers/google/cloud/hooks/gcs.py", line 490, in _call_with_retry
    f()
  File "/home/airflow/.local/lib/python3.7/site-packages/google/cloud/storage/blob.py", line 2697, in upload_from_filename
    retry=retry,
  File "/home/airflow/.local/lib/python3.7/site-packages/google/cloud/storage/blob.py", line 2553, in upload_from_file
    retry=retry,
  File "/home/airflow/.local/lib/python3.7/site-packages/google/cloud/storage/blob.py", line 2384, in _do_upload
    retry=retry,
  File "/home/airflow/.local/lib/python3.7/site-packages/google/cloud/storage/blob.py", line 2211, in _do_resumable_upload
    retry=retry,
  File "/home/airflow/.local/lib/python3.7/site-packages/google/cloud/storage/blob.py", line 2086, in _initiate_resumable_upload
    timeout=timeout,
  File "/home/airflow/.local/lib/python3.7/site-packages/google/resumable_media/requests/upload.py", line 421, in initiate
    retriable_request, self._get_status_code, self._retry_strategy
  File "/home/airflow/.local/lib/python3.7/site-packages/google/resumable_media/requests/_request_helpers.py", line 178, in wait_and_retry
    raise error
  File "/home/airflow/.local/lib/python3.7/site-packages/google/resumable_media/requests/_request_helpers.py", line 155, in wait_and_retry
    response = func()
  File "/home/airflow/.local/lib/python3.7/site-packages/google/resumable_media/requests/upload.py", line 413, in retriable_request
    method, url, data=payload, headers=headers, timeout=timeout
  File "/home/airflow/.local/lib/python3.7/site-packages/google/auth/transport/requests.py", line 555, in request
    **kwargs
  File "/home/airflow/.local/lib/python3.7/site-packages/requests/sessions.py", line 589, in request
    resp = self.send(prep, **send_kwargs)
  File "/home/airflow/.local/lib/python3.7/site-packages/requests/sessions.py", line 703, in send
    r = adapter.send(request, **kwargs)
  File "/home/airflow/.local/lib/python3.7/site-packages/requests/adapters.py", line 501, in send
    raise ConnectionError(err, request=request)
requests.exceptions.ConnectionError: ('Connection aborted.', RemoteDisconnected('Remote end closed connection without response'))
[2025-03-27T02:50:41.801+0000] {taskinstance.py:1350} INFO - Marking task as FAILED. dag_id=load_geolocation_postgres_to_bq, task_id=postgres_to_gcs_batch_12, execution_date=20250327T023501, start_date=20250327T025016, end_date=20250327T025041
[2025-03-27T02:50:41.914+0000] {standard_task_runner.py:109} ERROR - Failed to execute job 204 for task postgres_to_gcs_batch_12 (('Connection aborted.', RemoteDisconnected('Remote end closed connection without response')); 6743)
[2025-03-27T02:50:41.981+0000] {local_task_job_runner.py:225} INFO - Task exited with return code 1
[2025-03-27T02:50:42.166+0000] {taskinstance.py:2653} INFO - 0 downstream tasks scheduled from follow-on schedule check
