[2025-03-15T23:09:22.877+0000] {taskinstance.py:1103} INFO - Dependencies all met for dep_context=non-requeueable deps ti=<TaskInstance: transfer_to_bq.transfer_tasks.export_products_to_gcs manual__2025-03-15T23:08:59.706367+00:00 [queued]>
[2025-03-15T23:09:22.914+0000] {taskinstance.py:1103} INFO - Dependencies all met for dep_context=requeueable deps ti=<TaskInstance: transfer_to_bq.transfer_tasks.export_products_to_gcs manual__2025-03-15T23:08:59.706367+00:00 [queued]>
[2025-03-15T23:09:22.915+0000] {taskinstance.py:1308} INFO - Starting attempt 1 of 4
[2025-03-15T23:09:22.969+0000] {taskinstance.py:1327} INFO - Executing <Task(PostgresToGCSOperator): transfer_tasks.export_products_to_gcs> on 2025-03-15 23:08:59.706367+00:00
[2025-03-15T23:09:22.991+0000] {standard_task_runner.py:57} INFO - Started process 320 to run task
[2025-03-15T23:09:23.044+0000] {standard_task_runner.py:84} INFO - Running: ['airflow', 'tasks', 'run', 'transfer_to_bq', 'transfer_tasks.export_products_to_gcs', 'manual__2025-03-15T23:08:59.706367+00:00', '--job-id', '44', '--raw', '--subdir', 'DAGS_FOLDER/transfer_to_bq.py', '--cfg-path', '/tmp/tmpoe_ss9o0']
[2025-03-15T23:09:23.202+0000] {standard_task_runner.py:85} INFO - Job 44: Subtask transfer_tasks.export_products_to_gcs
[2025-03-15T23:09:23.620+0000] {logging_mixin.py:149} WARNING - /home/airflow/.local/lib/python3.7/site-packages/airflow/settings.py:195 DeprecationWarning: The sql_alchemy_conn option in [core] has been moved to the sql_alchemy_conn option in [database] - the old setting has been used, but please update your config.
[2025-03-15T23:09:28.088+0000] {task_command.py:410} INFO - Running <TaskInstance: transfer_to_bq.transfer_tasks.export_products_to_gcs manual__2025-03-15T23:08:59.706367+00:00 [running]> on host 003eb9c808ff
[2025-03-15T23:09:33.603+0000] {taskinstance.py:1547} INFO - Exporting env vars: AIRFLOW_CTX_DAG_OWNER='airflow' AIRFLOW_CTX_DAG_ID='transfer_to_bq' AIRFLOW_CTX_TASK_ID='transfer_tasks.export_products_to_gcs' AIRFLOW_CTX_EXECUTION_DATE='2025-03-15T23:08:59.706367+00:00' AIRFLOW_CTX_TRY_NUMBER='1' AIRFLOW_CTX_DAG_RUN_ID='manual__2025-03-15T23:08:59.706367+00:00'
[2025-03-15T23:09:33.631+0000] {sql_to_gcs.py:155} INFO - Executing query
[2025-03-15T23:09:34.160+0000] {base.py:73} INFO - Using connection ID 'postgres_default' for task execution.
[2025-03-15T23:09:37.274+0000] {sql_to_gcs.py:174} INFO - Writing local data files
[2025-03-15T23:09:43.612+0000] {sql_to_gcs.py:180} INFO - Uploading chunk file #0 to GCS.
[2025-03-15T23:09:46.807+0000] {base.py:73} INFO - Using connection ID 'google_cloud_default' for task execution.
[2025-03-15T23:11:28.138+0000] {taskinstance.py:1824} ERROR - Task failed with exception
Traceback (most recent call last):
  File "/home/airflow/.local/lib/python3.7/site-packages/urllib3/connectionpool.py", line 721, in urlopen
    chunked=chunked,
  File "/home/airflow/.local/lib/python3.7/site-packages/urllib3/connectionpool.py", line 415, in _make_request
    conn.request(method, url, **httplib_request_kw)
  File "/home/airflow/.local/lib/python3.7/site-packages/urllib3/connection.py", line 244, in request
    super(HTTPConnection, self).request(method, url, body=body, headers=headers)
  File "/usr/local/lib/python3.7/http/client.py", line 1281, in request
    self._send_request(method, url, body, headers, encode_chunked)
  File "/usr/local/lib/python3.7/http/client.py", line 1327, in _send_request
    self.endheaders(body, encode_chunked=encode_chunked)
  File "/usr/local/lib/python3.7/http/client.py", line 1276, in endheaders
    self._send_output(message_body, encode_chunked=encode_chunked)
  File "/usr/local/lib/python3.7/http/client.py", line 1075, in _send_output
    self.send(chunk)
  File "/usr/local/lib/python3.7/http/client.py", line 997, in send
    self.sock.sendall(data)
  File "/usr/local/lib/python3.7/ssl.py", line 1034, in sendall
    v = self.send(byte_view[count:])
  File "/usr/local/lib/python3.7/ssl.py", line 1003, in send
    return self._sslobj.write(data)
socket.timeout: The write operation timed out

During handling of the above exception, another exception occurred:

Traceback (most recent call last):
  File "/home/airflow/.local/lib/python3.7/site-packages/requests/adapters.py", line 497, in send
    chunked=chunked,
  File "/home/airflow/.local/lib/python3.7/site-packages/urllib3/connectionpool.py", line 799, in urlopen
    method, url, error=e, _pool=self, _stacktrace=sys.exc_info()[2]
  File "/home/airflow/.local/lib/python3.7/site-packages/urllib3/util/retry.py", line 550, in increment
    raise six.reraise(type(error), error, _stacktrace)
  File "/home/airflow/.local/lib/python3.7/site-packages/urllib3/packages/six.py", line 769, in reraise
    raise value.with_traceback(tb)
  File "/home/airflow/.local/lib/python3.7/site-packages/urllib3/connectionpool.py", line 721, in urlopen
    chunked=chunked,
  File "/home/airflow/.local/lib/python3.7/site-packages/urllib3/connectionpool.py", line 415, in _make_request
    conn.request(method, url, **httplib_request_kw)
  File "/home/airflow/.local/lib/python3.7/site-packages/urllib3/connection.py", line 244, in request
    super(HTTPConnection, self).request(method, url, body=body, headers=headers)
  File "/usr/local/lib/python3.7/http/client.py", line 1281, in request
    self._send_request(method, url, body, headers, encode_chunked)
  File "/usr/local/lib/python3.7/http/client.py", line 1327, in _send_request
    self.endheaders(body, encode_chunked=encode_chunked)
  File "/usr/local/lib/python3.7/http/client.py", line 1276, in endheaders
    self._send_output(message_body, encode_chunked=encode_chunked)
  File "/usr/local/lib/python3.7/http/client.py", line 1075, in _send_output
    self.send(chunk)
  File "/usr/local/lib/python3.7/http/client.py", line 997, in send
    self.sock.sendall(data)
  File "/usr/local/lib/python3.7/ssl.py", line 1034, in sendall
    v = self.send(byte_view[count:])
  File "/usr/local/lib/python3.7/ssl.py", line 1003, in send
    return self._sslobj.write(data)
urllib3.exceptions.ProtocolError: ('Connection aborted.', timeout('The write operation timed out'))

During handling of the above exception, another exception occurred:

Traceback (most recent call last):
  File "/home/airflow/.local/lib/python3.7/site-packages/airflow/providers/google/cloud/transfers/sql_to_gcs.py", line 181, in execute
    self._upload_to_gcs(file_to_upload)
  File "/home/airflow/.local/lib/python3.7/site-packages/airflow/providers/google/cloud/transfers/sql_to_gcs.py", line 475, in _upload_to_gcs
    metadata=metadata,
  File "/home/airflow/.local/lib/python3.7/site-packages/airflow/providers/google/cloud/hooks/gcs.py", line 533, in upload
    partial(blob.upload_from_filename, filename=filename, content_type=mime_type, timeout=timeout)
  File "/home/airflow/.local/lib/python3.7/site-packages/airflow/providers/google/cloud/hooks/gcs.py", line 490, in _call_with_retry
    f()
  File "/home/airflow/.local/lib/python3.7/site-packages/google/cloud/storage/blob.py", line 2697, in upload_from_filename
    retry=retry,
  File "/home/airflow/.local/lib/python3.7/site-packages/google/cloud/storage/blob.py", line 2553, in upload_from_file
    retry=retry,
  File "/home/airflow/.local/lib/python3.7/site-packages/google/cloud/storage/blob.py", line 2384, in _do_upload
    retry=retry,
  File "/home/airflow/.local/lib/python3.7/site-packages/google/cloud/storage/blob.py", line 2215, in _do_resumable_upload
    response = upload.transmit_next_chunk(transport, timeout=timeout)
  File "/home/airflow/.local/lib/python3.7/site-packages/google/resumable_media/requests/upload.py", line 516, in transmit_next_chunk
    retriable_request, self._get_status_code, self._retry_strategy
  File "/home/airflow/.local/lib/python3.7/site-packages/google/resumable_media/requests/_request_helpers.py", line 178, in wait_and_retry
    raise error
  File "/home/airflow/.local/lib/python3.7/site-packages/google/resumable_media/requests/_request_helpers.py", line 155, in wait_and_retry
    response = func()
  File "/home/airflow/.local/lib/python3.7/site-packages/google/resumable_media/requests/upload.py", line 508, in retriable_request
    method, url, data=payload, headers=headers, timeout=timeout
  File "/home/airflow/.local/lib/python3.7/site-packages/google/auth/transport/requests.py", line 555, in request
    **kwargs
  File "/home/airflow/.local/lib/python3.7/site-packages/requests/sessions.py", line 589, in request
    resp = self.send(prep, **send_kwargs)
  File "/home/airflow/.local/lib/python3.7/site-packages/requests/sessions.py", line 703, in send
    r = adapter.send(request, **kwargs)
  File "/home/airflow/.local/lib/python3.7/site-packages/requests/adapters.py", line 501, in send
    raise ConnectionError(err, request=request)
requests.exceptions.ConnectionError: ('Connection aborted.', timeout('The write operation timed out'))
[2025-03-15T23:11:34.973+0000] {taskinstance.py:1350} INFO - Marking task as UP_FOR_RETRY. dag_id=transfer_to_bq, task_id=transfer_tasks.export_products_to_gcs, execution_date=20250315T230859, start_date=20250315T230922, end_date=20250315T231134
[2025-03-15T23:11:37.116+0000] {standard_task_runner.py:109} ERROR - Failed to execute job 44 for task transfer_tasks.export_products_to_gcs (('Connection aborted.', timeout('The write operation timed out')); 320)
[2025-03-15T23:11:37.225+0000] {local_task_job_runner.py:225} INFO - Task exited with return code 1
[2025-03-15T23:11:39.337+0000] {taskinstance.py:2653} INFO - 0 downstream tasks scheduled from follow-on schedule check
