[2025-03-15T22:50:01.039+0000] {taskinstance.py:1103} INFO - Dependencies all met for dep_context=non-requeueable deps ti=<TaskInstance: postgres_to_bigquery_transfer.export_products_to_gcs manual__2025-03-15T22:42:31.418665+00:00 [queued]>
[2025-03-15T22:50:01.101+0000] {taskinstance.py:1103} INFO - Dependencies all met for dep_context=requeueable deps ti=<TaskInstance: postgres_to_bigquery_transfer.export_products_to_gcs manual__2025-03-15T22:42:31.418665+00:00 [queued]>
[2025-03-15T22:50:01.101+0000] {taskinstance.py:1308} INFO - Starting attempt 2 of 2
[2025-03-15T22:50:01.186+0000] {taskinstance.py:1327} INFO - Executing <Task(PostgresToGCSOperator): export_products_to_gcs> on 2025-03-15 22:42:31.418665+00:00
[2025-03-15T22:50:01.412+0000] {standard_task_runner.py:57} INFO - Started process 550 to run task
[2025-03-15T22:50:01.573+0000] {standard_task_runner.py:84} INFO - Running: ['airflow', 'tasks', 'run', 'postgres_to_bigquery_transfer', 'export_products_to_gcs', 'manual__2025-03-15T22:42:31.418665+00:00', '--job-id', '26', '--raw', '--subdir', 'DAGS_FOLDER/postgres_to_bigquery_transfer.py', '--cfg-path', '/tmp/tmpcubqtj2o']
[2025-03-15T22:50:01.732+0000] {standard_task_runner.py:85} INFO - Job 26: Subtask export_products_to_gcs
[2025-03-15T22:50:03.224+0000] {logging_mixin.py:149} WARNING - /home/airflow/.local/lib/python3.7/site-packages/airflow/settings.py:195 DeprecationWarning: The sql_alchemy_conn option in [core] has been moved to the sql_alchemy_conn option in [database] - the old setting has been used, but please update your config.
[2025-03-15T22:50:04.796+0000] {task_command.py:410} INFO - Running <TaskInstance: postgres_to_bigquery_transfer.export_products_to_gcs manual__2025-03-15T22:42:31.418665+00:00 [running]> on host 43c735050f20
[2025-03-15T22:50:06.085+0000] {taskinstance.py:1547} INFO - Exporting env vars: AIRFLOW_CTX_DAG_OWNER='airflow' AIRFLOW_CTX_DAG_ID='postgres_to_bigquery_transfer' AIRFLOW_CTX_TASK_ID='export_products_to_gcs' AIRFLOW_CTX_EXECUTION_DATE='2025-03-15T22:42:31.418665+00:00' AIRFLOW_CTX_TRY_NUMBER='2' AIRFLOW_CTX_DAG_RUN_ID='manual__2025-03-15T22:42:31.418665+00:00'
[2025-03-15T22:50:06.148+0000] {sql_to_gcs.py:155} INFO - Executing query
[2025-03-15T22:50:06.830+0000] {base.py:73} INFO - Using connection ID 'postgres_default' for task execution.
[2025-03-15T22:50:08.253+0000] {sql_to_gcs.py:174} INFO - Writing local data files
[2025-03-15T22:50:09.635+0000] {sql_to_gcs.py:180} INFO - Uploading chunk file #0 to GCS.
[2025-03-15T22:50:10.095+0000] {base.py:73} INFO - Using connection ID 'google_cloud_default' for task execution.
[2025-03-15T22:52:11.156+0000] {taskinstance.py:1824} ERROR - Task failed with exception
Traceback (most recent call last):
  File "/home/airflow/.local/lib/python3.7/site-packages/urllib3/connectionpool.py", line 466, in _make_request
    six.raise_from(e, None)
  File "<string>", line 3, in raise_from
  File "/home/airflow/.local/lib/python3.7/site-packages/urllib3/connectionpool.py", line 461, in _make_request
    httplib_response = conn.getresponse()
  File "/usr/local/lib/python3.7/http/client.py", line 1373, in getresponse
    response.begin()
  File "/usr/local/lib/python3.7/http/client.py", line 319, in begin
    version, status, reason = self._read_status()
  File "/usr/local/lib/python3.7/http/client.py", line 280, in _read_status
    line = str(self.fp.readline(_MAXLINE + 1), "iso-8859-1")
  File "/usr/local/lib/python3.7/socket.py", line 589, in readinto
    return self._sock.recv_into(b)
  File "/usr/local/lib/python3.7/ssl.py", line 1071, in recv_into
    return self.read(nbytes, buffer)
  File "/usr/local/lib/python3.7/ssl.py", line 929, in read
    return self._sslobj.read(len, buffer)
socket.timeout: The read operation timed out

During handling of the above exception, another exception occurred:

Traceback (most recent call last):
  File "/home/airflow/.local/lib/python3.7/site-packages/requests/adapters.py", line 497, in send
    chunked=chunked,
  File "/home/airflow/.local/lib/python3.7/site-packages/urllib3/connectionpool.py", line 799, in urlopen
    method, url, error=e, _pool=self, _stacktrace=sys.exc_info()[2]
  File "/home/airflow/.local/lib/python3.7/site-packages/urllib3/util/retry.py", line 550, in increment
    raise six.reraise(type(error), error, _stacktrace)
  File "/home/airflow/.local/lib/python3.7/site-packages/urllib3/packages/six.py", line 770, in reraise
    raise value
  File "/home/airflow/.local/lib/python3.7/site-packages/urllib3/connectionpool.py", line 721, in urlopen
    chunked=chunked,
  File "/home/airflow/.local/lib/python3.7/site-packages/urllib3/connectionpool.py", line 468, in _make_request
    self._raise_timeout(err=e, url=url, timeout_value=read_timeout)
  File "/home/airflow/.local/lib/python3.7/site-packages/urllib3/connectionpool.py", line 358, in _raise_timeout
    self, url, "Read timed out. (read timeout=%s)" % timeout_value
urllib3.exceptions.ReadTimeoutError: HTTPSConnectionPool(host='storage.googleapis.com', port=443): Read timed out. (read timeout=60)

During handling of the above exception, another exception occurred:

Traceback (most recent call last):
  File "/home/airflow/.local/lib/python3.7/site-packages/airflow/providers/google/cloud/transfers/sql_to_gcs.py", line 181, in execute
    self._upload_to_gcs(file_to_upload)
  File "/home/airflow/.local/lib/python3.7/site-packages/airflow/providers/google/cloud/transfers/sql_to_gcs.py", line 475, in _upload_to_gcs
    metadata=metadata,
  File "/home/airflow/.local/lib/python3.7/site-packages/airflow/providers/google/cloud/hooks/gcs.py", line 533, in upload
    partial(blob.upload_from_filename, filename=filename, content_type=mime_type, timeout=timeout)
  File "/home/airflow/.local/lib/python3.7/site-packages/airflow/providers/google/cloud/hooks/gcs.py", line 490, in _call_with_retry
    f()
  File "/home/airflow/.local/lib/python3.7/site-packages/google/cloud/storage/blob.py", line 2697, in upload_from_filename
    retry=retry,
  File "/home/airflow/.local/lib/python3.7/site-packages/google/cloud/storage/blob.py", line 2553, in upload_from_file
    retry=retry,
  File "/home/airflow/.local/lib/python3.7/site-packages/google/cloud/storage/blob.py", line 2384, in _do_upload
    retry=retry,
  File "/home/airflow/.local/lib/python3.7/site-packages/google/cloud/storage/blob.py", line 2215, in _do_resumable_upload
    response = upload.transmit_next_chunk(transport, timeout=timeout)
  File "/home/airflow/.local/lib/python3.7/site-packages/google/resumable_media/requests/upload.py", line 516, in transmit_next_chunk
    retriable_request, self._get_status_code, self._retry_strategy
  File "/home/airflow/.local/lib/python3.7/site-packages/google/resumable_media/requests/_request_helpers.py", line 178, in wait_and_retry
    raise error
  File "/home/airflow/.local/lib/python3.7/site-packages/google/resumable_media/requests/_request_helpers.py", line 155, in wait_and_retry
    response = func()
  File "/home/airflow/.local/lib/python3.7/site-packages/google/resumable_media/requests/upload.py", line 508, in retriable_request
    method, url, data=payload, headers=headers, timeout=timeout
  File "/home/airflow/.local/lib/python3.7/site-packages/google/auth/transport/requests.py", line 555, in request
    **kwargs
  File "/home/airflow/.local/lib/python3.7/site-packages/requests/sessions.py", line 589, in request
    resp = self.send(prep, **send_kwargs)
  File "/home/airflow/.local/lib/python3.7/site-packages/requests/sessions.py", line 703, in send
    r = adapter.send(request, **kwargs)
  File "/home/airflow/.local/lib/python3.7/site-packages/requests/adapters.py", line 532, in send
    raise ReadTimeout(e, request=request)
requests.exceptions.ReadTimeout: HTTPSConnectionPool(host='storage.googleapis.com', port=443): Read timed out. (read timeout=60)
[2025-03-15T22:52:11.341+0000] {taskinstance.py:1350} INFO - Marking task as FAILED. dag_id=postgres_to_bigquery_transfer, task_id=export_products_to_gcs, execution_date=20250315T224231, start_date=20250315T225001, end_date=20250315T225211
[2025-03-15T22:52:11.399+0000] {standard_task_runner.py:109} ERROR - Failed to execute job 26 for task export_products_to_gcs (HTTPSConnectionPool(host='storage.googleapis.com', port=443): Read timed out. (read timeout=60); 550)
[2025-03-15T22:52:11.477+0000] {local_task_job_runner.py:225} INFO - Task exited with return code 1
[2025-03-15T22:52:11.572+0000] {taskinstance.py:2653} INFO - 0 downstream tasks scheduled from follow-on schedule check
