[2025-03-15T22:10:33.586+0000] {taskinstance.py:1103} INFO - Dependencies all met for dep_context=non-requeueable deps ti=<TaskInstance: postgres_data_ingestion.ingest_geolocation_data manual__2025-03-15T22:10:27.297068+00:00 [queued]>
[2025-03-15T22:10:33.616+0000] {taskinstance.py:1103} INFO - Dependencies all met for dep_context=requeueable deps ti=<TaskInstance: postgres_data_ingestion.ingest_geolocation_data manual__2025-03-15T22:10:27.297068+00:00 [queued]>
[2025-03-15T22:10:33.623+0000] {taskinstance.py:1308} INFO - Starting attempt 1 of 2
[2025-03-15T22:10:33.671+0000] {taskinstance.py:1327} INFO - Executing <Task(PythonOperator): ingest_geolocation_data> on 2025-03-15 22:10:27.297068+00:00
[2025-03-15T22:10:33.707+0000] {standard_task_runner.py:57} INFO - Started process 433 to run task
[2025-03-15T22:10:33.747+0000] {standard_task_runner.py:84} INFO - Running: ['airflow', 'tasks', 'run', 'postgres_data_ingestion', 'ingest_geolocation_data', 'manual__2025-03-15T22:10:27.297068+00:00', '--job-id', '52', '--raw', '--subdir', 'DAGS_FOLDER/data_ingestion_dag.py', '--cfg-path', '/tmp/tmpl5msnvhc']
[2025-03-15T22:10:33.780+0000] {standard_task_runner.py:85} INFO - Job 52: Subtask ingest_geolocation_data
[2025-03-15T22:10:34.060+0000] {logging_mixin.py:149} WARNING - /home/airflow/.local/lib/python3.7/site-packages/airflow/settings.py:195 DeprecationWarning: The sql_alchemy_conn option in [core] has been moved to the sql_alchemy_conn option in [database] - the old setting has been used, but please update your config.
[2025-03-15T22:10:34.716+0000] {task_command.py:410} INFO - Running <TaskInstance: postgres_data_ingestion.ingest_geolocation_data manual__2025-03-15T22:10:27.297068+00:00 [running]> on host fb89872f45b6
[2025-03-15T22:10:35.020+0000] {taskinstance.py:1547} INFO - Exporting env vars: AIRFLOW_CTX_DAG_OWNER='Blessing' AIRFLOW_CTX_DAG_ID='postgres_data_ingestion' AIRFLOW_CTX_TASK_ID='ingest_geolocation_data' AIRFLOW_CTX_EXECUTION_DATE='2025-03-15T22:10:27.297068+00:00' AIRFLOW_CTX_TRY_NUMBER='1' AIRFLOW_CTX_DAG_RUN_ID='manual__2025-03-15T22:10:27.297068+00:00'
[2025-03-15T22:10:35.033+0000] {taskinstance.py:1824} ERROR - Task failed with exception
Traceback (most recent call last):
  File "/home/airflow/.local/lib/python3.7/site-packages/airflow/operators/python.py", line 181, in execute
    return_value = self.execute_callable()
  File "/home/airflow/.local/lib/python3.7/site-packages/airflow/operators/python.py", line 198, in execute_callable
    return self.python_callable(*self.op_args, **self.op_kwargs)
  File "/opt/airflow/dags/data_ingestion_dag.py", line 53, in ingest_table_data
    engine = create_engine(f'postgresql+psycopg2://{db_user}:{db_password}@{db_host}:{db_port}/{db_name}')
  File "<string>", line 2, in create_engine
  File "/home/airflow/.local/lib/python3.7/site-packages/sqlalchemy/util/deprecations.py", line 375, in warned
    return fn(*args, **kwargs)
  File "/home/airflow/.local/lib/python3.7/site-packages/sqlalchemy/engine/create.py", line 514, in create_engine
    u = _url.make_url(url)
  File "/home/airflow/.local/lib/python3.7/site-packages/sqlalchemy/engine/url.py", line 738, in make_url
    return _parse_url(name_or_url)
  File "/home/airflow/.local/lib/python3.7/site-packages/sqlalchemy/engine/url.py", line 794, in _parse_url
    components["port"] = int(components["port"])
ValueError: invalid literal for int() with base 10: 'None'
[2025-03-15T22:10:35.081+0000] {taskinstance.py:1350} INFO - Marking task as UP_FOR_RETRY. dag_id=postgres_data_ingestion, task_id=ingest_geolocation_data, execution_date=20250315T221027, start_date=20250315T221033, end_date=20250315T221035
[2025-03-15T22:10:35.124+0000] {standard_task_runner.py:109} ERROR - Failed to execute job 52 for task ingest_geolocation_data (invalid literal for int() with base 10: 'None'; 433)
[2025-03-15T22:10:35.158+0000] {local_task_job_runner.py:225} INFO - Task exited with return code 1
[2025-03-15T22:10:35.305+0000] {taskinstance.py:2653} INFO - 0 downstream tasks scheduled from follow-on schedule check
