[2025-03-15T21:09:51.457+0000] {taskinstance.py:1103} INFO - Dependencies all met for dep_context=non-requeueable deps ti=<TaskInstance: postgres_data_ingestion.ingest_product_category_name_translation_data manual__2025-03-15T21:09:19.199161+00:00 [queued]>
[2025-03-15T21:09:51.515+0000] {taskinstance.py:1103} INFO - Dependencies all met for dep_context=requeueable deps ti=<TaskInstance: postgres_data_ingestion.ingest_product_category_name_translation_data manual__2025-03-15T21:09:19.199161+00:00 [queued]>
[2025-03-15T21:09:51.517+0000] {taskinstance.py:1308} INFO - Starting attempt 1 of 2
[2025-03-15T21:09:51.594+0000] {taskinstance.py:1327} INFO - Executing <Task(PythonOperator): ingest_product_category_name_translation_data> on 2025-03-15 21:09:19.199161+00:00
[2025-03-15T21:09:51.756+0000] {standard_task_runner.py:57} INFO - Started process 319 to run task
[2025-03-15T21:09:52.418+0000] {standard_task_runner.py:84} INFO - Running: ['airflow', 'tasks', 'run', 'postgres_data_ingestion', 'ingest_product_category_name_translation_data', 'manual__2025-03-15T21:09:19.199161+00:00', '--job-id', '8', '--raw', '--subdir', 'DAGS_FOLDER/data_ingestion_dag.py', '--cfg-path', '/tmp/tmphco7rsrk']
[2025-03-15T21:09:52.668+0000] {standard_task_runner.py:85} INFO - Job 8: Subtask ingest_product_category_name_translation_data
[2025-03-15T21:09:53.935+0000] {logging_mixin.py:149} WARNING - /home/airflow/.local/lib/python3.7/site-packages/airflow/settings.py:195 DeprecationWarning: The sql_alchemy_conn option in [core] has been moved to the sql_alchemy_conn option in [database] - the old setting has been used, but please update your config.
[2025-03-15T21:09:58.065+0000] {task_command.py:410} INFO - Running <TaskInstance: postgres_data_ingestion.ingest_product_category_name_translation_data manual__2025-03-15T21:09:19.199161+00:00 [running]> on host 8224d49c25d3
[2025-03-15T21:10:00.062+0000] {taskinstance.py:1547} INFO - Exporting env vars: AIRFLOW_CTX_DAG_OWNER='Blessing' AIRFLOW_CTX_DAG_ID='postgres_data_ingestion' AIRFLOW_CTX_TASK_ID='ingest_product_category_name_translation_data' AIRFLOW_CTX_EXECUTION_DATE='2025-03-15T21:09:19.199161+00:00' AIRFLOW_CTX_TRY_NUMBER='1' AIRFLOW_CTX_DAG_RUN_ID='manual__2025-03-15T21:09:19.199161+00:00'
[2025-03-15T21:10:00.746+0000] {logging_mixin.py:149} INFO - Ingesting data into the 'product_category_name_translation' table...
[2025-03-15T21:10:00.874+0000] {logging_mixin.py:149} INFO - Error ingesting data into the 'product_category_name_translation' table: (psycopg2.OperationalError) connection to server at "postgres" (172.24.0.2), port 5432 failed: FATAL:  password authentication failed for user "None"

(Background on this error at: https://sqlalche.me/e/14/e3q8)
[2025-03-15T21:10:00.902+0000] {taskinstance.py:1824} ERROR - Task failed with exception
Traceback (most recent call last):
  File "/home/airflow/.local/lib/python3.7/site-packages/sqlalchemy/engine/base.py", line 3366, in _wrap_pool_connect
    return fn()
  File "/home/airflow/.local/lib/python3.7/site-packages/sqlalchemy/pool/base.py", line 327, in connect
    return _ConnectionFairy._checkout(self)
  File "/home/airflow/.local/lib/python3.7/site-packages/sqlalchemy/pool/base.py", line 894, in _checkout
    fairy = _ConnectionRecord.checkout(pool)
  File "/home/airflow/.local/lib/python3.7/site-packages/sqlalchemy/pool/base.py", line 493, in checkout
    rec = pool._do_get()
  File "/home/airflow/.local/lib/python3.7/site-packages/sqlalchemy/pool/impl.py", line 146, in _do_get
    self._dec_overflow()
  File "/home/airflow/.local/lib/python3.7/site-packages/sqlalchemy/util/langhelpers.py", line 72, in __exit__
    with_traceback=exc_tb,
  File "/home/airflow/.local/lib/python3.7/site-packages/sqlalchemy/util/compat.py", line 211, in raise_
    raise exception
  File "/home/airflow/.local/lib/python3.7/site-packages/sqlalchemy/pool/impl.py", line 143, in _do_get
    return self._create_connection()
  File "/home/airflow/.local/lib/python3.7/site-packages/sqlalchemy/pool/base.py", line 273, in _create_connection
    return _ConnectionRecord(self)
  File "/home/airflow/.local/lib/python3.7/site-packages/sqlalchemy/pool/base.py", line 388, in __init__
    self.__connect()
  File "/home/airflow/.local/lib/python3.7/site-packages/sqlalchemy/pool/base.py", line 691, in __connect
    pool.logger.debug("Error on connect(): %s", e)
  File "/home/airflow/.local/lib/python3.7/site-packages/sqlalchemy/util/langhelpers.py", line 72, in __exit__
    with_traceback=exc_tb,
  File "/home/airflow/.local/lib/python3.7/site-packages/sqlalchemy/util/compat.py", line 211, in raise_
    raise exception
  File "/home/airflow/.local/lib/python3.7/site-packages/sqlalchemy/pool/base.py", line 686, in __connect
    self.dbapi_connection = connection = pool._invoke_creator(self)
  File "/home/airflow/.local/lib/python3.7/site-packages/sqlalchemy/engine/create.py", line 574, in connect
    return dialect.connect(*cargs, **cparams)
  File "/home/airflow/.local/lib/python3.7/site-packages/sqlalchemy/engine/default.py", line 598, in connect
    return self.dbapi.connect(*cargs, **cparams)
  File "/home/airflow/.local/lib/python3.7/site-packages/psycopg2/__init__.py", line 122, in connect
    conn = _connect(dsn, connection_factory=connection_factory, **kwasync)
psycopg2.OperationalError: connection to server at "postgres" (172.24.0.2), port 5432 failed: FATAL:  password authentication failed for user "None"


The above exception was the direct cause of the following exception:

Traceback (most recent call last):
  File "/home/airflow/.local/lib/python3.7/site-packages/airflow/operators/python.py", line 181, in execute
    return_value = self.execute_callable()
  File "/home/airflow/.local/lib/python3.7/site-packages/airflow/operators/python.py", line 198, in execute_callable
    return self.python_callable(*self.op_args, **self.op_kwargs)
  File "/opt/airflow/dags/data_ingestion_dag.py", line 69, in ingest_table_data
    raise e
  File "/opt/airflow/dags/data_ingestion_dag.py", line 61, in ingest_table_data
    with engine.connect() as connection:
  File "/home/airflow/.local/lib/python3.7/site-packages/sqlalchemy/engine/base.py", line 3320, in connect
    return self._connection_cls(self, close_with_result=close_with_result)
  File "/home/airflow/.local/lib/python3.7/site-packages/sqlalchemy/engine/base.py", line 96, in __init__
    else engine.raw_connection()
  File "/home/airflow/.local/lib/python3.7/site-packages/sqlalchemy/engine/base.py", line 3399, in raw_connection
    return self._wrap_pool_connect(self.pool.connect, _connection)
  File "/home/airflow/.local/lib/python3.7/site-packages/sqlalchemy/engine/base.py", line 3370, in _wrap_pool_connect
    e, dialect, self
  File "/home/airflow/.local/lib/python3.7/site-packages/sqlalchemy/engine/base.py", line 2204, in _handle_dbapi_exception_noconnection
    sqlalchemy_exception, with_traceback=exc_info[2], from_=e
  File "/home/airflow/.local/lib/python3.7/site-packages/sqlalchemy/util/compat.py", line 211, in raise_
    raise exception
  File "/home/airflow/.local/lib/python3.7/site-packages/sqlalchemy/engine/base.py", line 3366, in _wrap_pool_connect
    return fn()
  File "/home/airflow/.local/lib/python3.7/site-packages/sqlalchemy/pool/base.py", line 327, in connect
    return _ConnectionFairy._checkout(self)
  File "/home/airflow/.local/lib/python3.7/site-packages/sqlalchemy/pool/base.py", line 894, in _checkout
    fairy = _ConnectionRecord.checkout(pool)
  File "/home/airflow/.local/lib/python3.7/site-packages/sqlalchemy/pool/base.py", line 493, in checkout
    rec = pool._do_get()
  File "/home/airflow/.local/lib/python3.7/site-packages/sqlalchemy/pool/impl.py", line 146, in _do_get
    self._dec_overflow()
  File "/home/airflow/.local/lib/python3.7/site-packages/sqlalchemy/util/langhelpers.py", line 72, in __exit__
    with_traceback=exc_tb,
  File "/home/airflow/.local/lib/python3.7/site-packages/sqlalchemy/util/compat.py", line 211, in raise_
    raise exception
  File "/home/airflow/.local/lib/python3.7/site-packages/sqlalchemy/pool/impl.py", line 143, in _do_get
    return self._create_connection()
  File "/home/airflow/.local/lib/python3.7/site-packages/sqlalchemy/pool/base.py", line 273, in _create_connection
    return _ConnectionRecord(self)
  File "/home/airflow/.local/lib/python3.7/site-packages/sqlalchemy/pool/base.py", line 388, in __init__
    self.__connect()
  File "/home/airflow/.local/lib/python3.7/site-packages/sqlalchemy/pool/base.py", line 691, in __connect
    pool.logger.debug("Error on connect(): %s", e)
  File "/home/airflow/.local/lib/python3.7/site-packages/sqlalchemy/util/langhelpers.py", line 72, in __exit__
    with_traceback=exc_tb,
  File "/home/airflow/.local/lib/python3.7/site-packages/sqlalchemy/util/compat.py", line 211, in raise_
    raise exception
  File "/home/airflow/.local/lib/python3.7/site-packages/sqlalchemy/pool/base.py", line 686, in __connect
    self.dbapi_connection = connection = pool._invoke_creator(self)
  File "/home/airflow/.local/lib/python3.7/site-packages/sqlalchemy/engine/create.py", line 574, in connect
    return dialect.connect(*cargs, **cparams)
  File "/home/airflow/.local/lib/python3.7/site-packages/sqlalchemy/engine/default.py", line 598, in connect
    return self.dbapi.connect(*cargs, **cparams)
  File "/home/airflow/.local/lib/python3.7/site-packages/psycopg2/__init__.py", line 122, in connect
    conn = _connect(dsn, connection_factory=connection_factory, **kwasync)
sqlalchemy.exc.OperationalError: (psycopg2.OperationalError) connection to server at "postgres" (172.24.0.2), port 5432 failed: FATAL:  password authentication failed for user "None"

(Background on this error at: https://sqlalche.me/e/14/e3q8)
[2025-03-15T21:10:01.244+0000] {taskinstance.py:1350} INFO - Marking task as UP_FOR_RETRY. dag_id=postgres_data_ingestion, task_id=ingest_product_category_name_translation_data, execution_date=20250315T210919, start_date=20250315T210951, end_date=20250315T211001
[2025-03-15T21:10:01.448+0000] {standard_task_runner.py:109} ERROR - Failed to execute job 8 for task ingest_product_category_name_translation_data ((psycopg2.OperationalError) connection to server at "postgres" (172.24.0.2), port 5432 failed: FATAL:  password authentication failed for user "None"

(Background on this error at: https://sqlalche.me/e/14/e3q8); 319)
[2025-03-15T21:10:01.625+0000] {local_task_job_runner.py:225} INFO - Task exited with return code 1
[2025-03-15T21:10:02.039+0000] {taskinstance.py:2653} INFO - 0 downstream tasks scheduled from follow-on schedule check
